Workbook
Name _top: 'Min. Intérieur'!$T$33
Name Applicabilité: #REF!
Name Applicable: #REF!
Name Aucun: #REF!
Name Défini: #REF!
Name FiscalYear: #REF!
Name Initial: #REF!
Name Maitrisé: #REF!
Name Niveau_de_conformité: #REF!
Name Niveau_de_maturité: #REF!
Name Optimisation: #REF!
Name Reproductible: #REF!

Sheet Revision History
B8: Document Revision History
B9: Project Name: | C9: QHCs et reporting qualité FY27
B11: Document Status (e.g. Draft, Final, Release #): | E11: Final
B13: Document Version | C13: Date | D13: Prepared / Modified By | E13: Approved by | F13: Section and Text Revised
C14: 46301 | D14: Quality Team | E14: Ilham ELFATEHI | F14: Evaluation des performances des comptes
C15: 46189 | D15: Farah ABID | E15: Ilham ELFATEHI | F15: Revue des formules des scores de maturité et badges de performances
B20: Template Revision History
B22: Change Request# | C22: Template Version | D22: Approval Date | E22: Modified By | F22: Section, Page(s) and Text Revised
B23: NA | C23: 1.0 | D23: 41962 | E23: Ilham ELFATEHI | F23: Création du document
B24: NA | C24: 1.1 | D24: 42794 | E24: Ilham ELFATEHI | F24: Revue du template (new logo HPE CDG)
B25: NA | C25: 1.2 | D25: 42901 | E25: Ilham ELFATEHI | F25: Revue du template (Logo DXC)
B26: NA | C26: 1.3 | D26: 44417 | E26: Ilham ELFATEHI | F26: Revue template (New logo DXC)
B27: NA | C27: 1.4 | D27: 44656 | E27: Farah ABID | F27: Revue template (Document classification)
B28: NA | C28: 1.5 | D28: 45224 | E28: Farah ABID | F28: Revue template et Rajout de la liste déroulante des clause ISO9K de la partie reporting
B29: NA | C29: 1.6 | D29: 45428 | E29: Imane KAICHOUH | F29: Template Review (New logo DXC CDG, New Document Classification)
B30: CR-112 | C30: 1.7 | D30: 45763 | E30: Quality Team | F30: Template Review (Labeling change Quality Health Checks instead of audit)
B31: CR-114 | C31: 1,8 | D31: 45996 | E31: Quality Team | F31: Rajout de la catégorie 4 des findings
B32: NA | C32: 1.9 | D32: 46146 | E32: Ilham ELFATEHI | F32: Automatisation du fichier ajout évaluation de maturité, régle de gestion et indicateurs de perfomance
B33: NA | C33: 2.0 | D33: 46164 | E33: Ilham ELFATEHI | F33: Revue du template et automatisation des KPI's
B34: NA | C34: 2.1 | D34: 46188 | E34: Ilham ELFATEHI | F34: Instaurer des nouveaux barémes de maturité conforme à ISO 9001

Sheet ACCUEIL
B2: QHC ISO 9001:2015 — FY27
B3: DXC Technology Morocco | Quality Health Check
B4: Préparé par: Ilham EL FATEHI | Approuvé par: Mohamed HADID
B6: 📋 20 Comptes | 37 Clauses | 21 Colonnes | Score 1-4 | Catégorisation CSAT
B12: Palette DXC :
B13: Midnight Blue | C13: #0E1020
B14: Royal | C14: #004AAC
B15: Sky | C15: #A1E6FF
B16: Red | C16: #D94000
B17: Gold | C17: #FFAE41
B18: Canvas | C18: #F6F3F0
B19: Peach | C19: #FFC082
B20: Charcoal | C20: #2B2B2B

Sheet REGLES DE GESTION
A1: RÈGLES DE GESTION — QHC ISO 9001:2015 FY27
A3: Scoring DE MATURITÉ ISO 9001 (Échelle 1 à 5)
A4: Score | B4: Niveau de Maturité | C4: Description
A5: 1 | B5: Non en place / Élémentaire | C5: Aucune approche structurée, pratiques ad hoc
A6: 2 | B6: Partiellement en place / Réactif | C6: Approche réactive, documentation partielle
A7: 3 | B7: Largement en place / Stable | C7: Processus formalisés, mis en œuvre de manière cohérente
A8: 4 | B8: Totalement en place / Proactif | C8: Amélioration continue, indicateurs suivis
A9: 5 | B9: Excellence / Meilleures pratiques | C9: Performance durable, benchmarking, innovation
A10: 2. CATÉGORISATION COMPTES (alignée CSAT/NPS)
A12: Badge | B12: Seuil Score maturité | C12: Couleur | D12: Signification | E12: Action Requise
A13: 🟢 Très Performant | B13: ≥ 4.5 | C13: Vert | D13: SMQ mature et efficace | E13: Maintenir, partager BP
A14: 🔵 Performant | B14: 3.5 à 4.4 | C14: Bleu | D14: SMQ en place avec axes d'amélioration | E14: Amélioration continue
A15: 🟡 A surveiller | B15: 2.5 à 3.4 | C15: Jaune | D15: SMQ partiel, en développement | E15: Plan amélioration structuré
A16: 🟠 À Risque | B16: 1.5 à 2.4 | C16: Orange | D16: SMQ insuffisant, risques identifiés | E16: Plan prioritaire mensuel
A17: 🔴 Critique | B17: < 1.5 | C17: Rouge | D17: SMQ défaillant, NC majeures | E17: Action immédiate 30j
A20: 3. CATÉGORISATION DES FINDING
A22: Catégorie | B22: Définition | C22: Impact | D22: Délai | E22: Couleur
A23: NC Majeure | B23: Absence complète ou défaillance majeure du SMQ | C23: Critique | D23: ≤ 30 jours | E23: Rouge
A24: NC Mineure | B24: Défaillance occasionnelle par rapport aux exigences | C24: Modéré | D24: ≤ 60 jours | E24: Orange
A25: Observation | B25: Constat général sur le SMQ, risque potentiel | C25: Faible | D25: ≤ 90 jours | E25: Jaune
A26: OFI | B26: Piste d'amélioration identifiée | C26: Positif | D26: Selon priorités | E26: Bleu
A27: Bonne Pratique | B27: Pratique exemplaire à valoriser | C27: Positif | D27: Partage immédiat | E27: Vert
A30: 4. GESTION DES ACTIONS CORRECTIVES
A32: Statut | B32: Définition | C32: Règle | D32: Couleur
A33: Ouvert | B33: Action définie, pas encore démarrée | C33: Délai obligatoire | D33: Rouge
A34: En cours | B34: Action en cours de réalisation | C34: Suivi hebdomadaire | D34: Orange
A35: Clôturé | B35: Action réalisée et efficacité vérifiée | C35: Preuve obligatoire | D35: Vert
A36: Non applicable | B36: Action non pertinente | C36: Justification documentée | D36: Gris
A39: 5. INDICATEURS ÂGE
A41: Indicateur | B41: Seuil | C41: Action
A42: 🟢 Normal | B42: ≤ 30 jours | C42: Suivi normal
A43: 🟠 Alerte | B43: ≤ 60 jours | C43: Relance, escalade N+1
A44: 🔴 Critique | B44: > 90 jours | C44: Escalade management
A46: 6. CATÉGORIE (Category)
A48: Catégorie | B48: Définition | C48: Exemple
A49: Entité | B49: Applicable au niveau de l'entité DXC Morocco | C49: Politique qualité, Revue de direction
A50: Entité et Compte | B50: Applicable à la fois entité et compte | C50: Gestion des risques, Compétences
A51: Compte | B51: Applicable uniquement au niveau du compte client | C51: Satisfaction client, Exigences client

Sheet DASHBOARD AUDITS
B1: DASHBOARD RÉALISATION DES AUDITS — FY27
B3: INDICATEURS DE RÉALISATION
B4: Audits Planifiés | D4: Audits Réalisés | F4: En Cours | H4: Non Démarrés | J4: % Avancement
B5: 20 | D5: =COUNTIF(H12:H31,"Réalisé") -> 6 | F5: =COUNTIF(H12:H31,"En cours") -> 4 | H5: =COUNTIF(H12:H31,"Planifié") -> 10 | J5: =IFERROR(COUNTIF(H12:H31,"Réalisé")/20,0) -> 0.3
B7: TOTAL FINDINGS
B8: NC Maj | D8: NC Min | F8: Obs | H8: OFI | J8: BP | L8: TOTAL
B9: ='CDG Sécurité'!D10+RAM!C10+'Min. Intérieur'!C10+'CDG Capital'!C10+AtlanticRe!C10+'Client A'!C10+Servier!C10+MEN!C10+ADM!C10+'CDG DC'!C10+'CDG ITOC'!C10+BPOST!C10+'Graphtalk AIA'!C10+'ONCF APPS'!C10+'ONCF MW'!C10+ANEF!C10+Carrefour!C10+'Vinci Construction'!C10+AXA!C10+OCP!C10 -> 1 | D9: ='CDG Sécurité'!E10+RAM!D10+'Min. Intérieur'!D10+'CDG Capital'!D10+AtlanticRe!D10+'Client A'!D10+Servier!D10+MEN!D10+ADM!D10+'CDG DC'!D10+'CDG ITOC'!D10+BPOST!D10+'Graphtalk AIA'!D10+'ONCF APPS'!D10+'ONCF MW'!D10+ANEF!D10+Carrefour!D10+'Vinci Construction'!D10+AXA!D10+OCP!D10 -> 44 | F9: ='CDG Sécurité'!F10+RAM!E10+'Min. Intérieur'!E10+'CDG Capital'!E10+AtlanticRe!E10+'Client A'!E10+Servier!E10+MEN!E10+ADM!E10+'CDG DC'!E10+'CDG ITOC'!E10+BPOST!E10+'Graphtalk AIA'!E10+'ONCF APPS'!E10+'ONCF MW'!E10+ANEF!E10+Carrefour!E10+'Vinci Construction'!E10+AXA!E10+OCP!E10 -> 6 | H9: ='CDG Sécurité'!G10+RAM!F10+'Min. Intérieur'!F10+'CDG Capital'!F10+AtlanticRe!F10+'Client A'!F10+Servier!F10+MEN!F10+ADM!F10+'CDG DC'!F10+'CDG ITOC'!F10+BPOST!F10+'Graphtalk AIA'!F10+'ONCF APPS'!F10+'ONCF MW'!F10+ANEF!F10+Carrefour!F10+'Vinci Construction'!F10+AXA!F10+OCP!F10 -> 0 | J9: ='CDG Sécurité'!H10+RAM!G10+'Min. Intérieur'!G10+'CDG Capital'!G10+AtlanticRe!G10+'Client A'!G10+Servier!G10+MEN!G10+ADM!G10+'CDG DC'!G10+'CDG ITOC'!G10+BPOST!G10+'Graphtalk AIA'!G10+'ONCF APPS'!G10+'ONCF MW'!G10+ANEF!G10+Carrefour!G10+'Vinci Construction'!G10+AXA!G10+OCP!G10 -> 7 | L9: =B9+D9+F9+H9+J9 -> 58
B11: N° | C11: Compte | D11: Auditeur | E11: Date Plan. | F11: Date Réelle | G11: Durée | H11: Statut | I11: Score | J11: Badge | K11: Total Find.
B12: 1 | C12: CDG Sécurité | D12: Farah ABID | E12: 46146 | F12: 46149 | H12: En cours | I12: ='CDG Sécurité'!B10 -> 2.3636364 | J12: ='CDG Sécurité'!C10 -> À Risque | K12: ='CDG Sécurité'!I10 -> 7
B13: 2 | C13: RAM | D13: Imane KAICHOUH | E13: 46147 | F13: 46153 | H13: Réalisé | I13: =RAM!A10 -> 3.1538462 | J13: =RAM!B10 -> A Surveiller | K13: =RAM!H10 -> 5
B14: 3 | C14: Min. Intérieur | D14: Farah ABID | E14: 46148 | F14: 46154 | H14: Réalisé | I14: ='Min. Intérieur'!A10 -> 3.3636364 | J14: ='Min. Intérieur'!B10 -> A Surveiller | K14: ='Min. Intérieur'!H10 -> 7
B15: 4 | C15: CDG Capital | D15: Imane KAICHOUH | E15: 46149 | F15: 46155 | H15: En cours | I15: ='CDG Capital'!A10 -> 2.4545455 | J15: ='CDG Capital'!B10 -> À Risque | K15: ='CDG Capital'!H10 -> 7
B16: 5 | C16: AtlanticRe | D16: Imane KAICHOUH | E16: 46146 | F16: 46147 | H16: Réalisé | I16: =AtlanticRe!A10 -> 2.9615385 | J16: =AtlanticRe!B10 -> A Surveiller | K16: =AtlanticRe!H10 -> 5
B17: 6 | C17: Client A | H17: Planifié | I17: ='Client A'!A10 -> 0 | J17: ='Client A'!B10 -> ⏳ Non audité | K17: ='Client A'!H10 -> 0
B18: 7 | C18: Servier | D18: Farah ABID | E18: 46157 | F18: 46174 | H18: Réalisé | I18: =Servier!A10 -> 3.6 | J18: =Servier!B10 -> Performant | K18: =Servier!H10 -> 4
B19: 8 | C19: MEN | H19: En cours | I19: =MEN!A10 -> 3.1538462 | J19: =MEN!B10 -> A Surveiller | K19: =MEN!H10 -> 5
B20: 9 | C20: ADM | H20: Planifié | I20: =ADM!A10 -> 0 | J20: =ADM!B10 -> ⏳ Non audité | K20: =ADM!H10 -> 0
B21: 10 | C21: CDG DC | H21: Planifié | I21: ='CDG DC'!A10 -> 0 | J21: ='CDG DC'!B10 -> ⏳ Non audité | K21: ='CDG DC'!H10 -> 0
B22: 11 | C22: CDG ITOC | H22: Planifié | I22: ='CDG ITOC'!A10 -> 0 | J22: ='CDG ITOC'!B10 -> ⏳ Non audité | K22: ='CDG ITOC'!H10 -> 0
B23: 12 | C23: BPOST | H23: Planifié | I23: =BPOST!A10 -> 0 | J23: =BPOST!B10 -> ⏳ Non audité | K23: =BPOST!H10 -> 0
B24: 13 | C24: Graphtalk AIA | H24: Planifié | I24: ='Graphtalk AIA'!A10 -> 0 | J24: ='Graphtalk AIA'!B10 -> ⏳ Non audité | K24: ='Graphtalk AIA'!H10 -> 0
B25: 14 | C25: ONCF APPS | H25: Réalisé | I25: ='ONCF APPS'!A10 -> 0 | J25: ='ONCF APPS'!B10 -> ⏳ Non audité | K25: ='ONCF APPS'!H10 -> 0
B26: 15 | C26: ONCF MW | H26: Réalisé | I26: ='ONCF MW'!A10 -> 3.1153846 | J26: ='ONCF MW'!B10 -> A Surveiller | K26: ='ONCF MW'!H10 -> 6
B27: 16 | C27: ANEF | H27: Planifié | I27: =ANEF!A10 -> 0 | J27: =ANEF!B10 -> ⏳ Non audité | K27: =ANEF!H10 -> 0
B28: 17 | C28: Carrefour | H28: Planifié | I28: =Carrefour!A10 -> 0 | J28: =Carrefour!B10 -> ⏳ Non audité | K28: =Carrefour!H10 -> 0
B29: 18 | C29: Vinci Construction | H29: Planifié | I29: ='Vinci Construction'!A10 -> 0 | J29: ='Vinci Construction'!B10 -> ⏳ Non audité | K29: ='Vinci Construction'!H10 -> 0
B30: 19 | C30: AXA | H30: Planifié | I30: =AXA!A10 -> 0 | J30: =AXA!B10 -> ⏳ Non audité | K30: =AXA!H10 -> 0
B31: 20 | C31: OCP | H31: En cours | I31: =OCP!A10 -> 3.1538462 | J31: =OCP!B10 -> A Surveiller | K31: =OCP!H10 -> 5

Sheet CONSOLIDATION
A1: CONSOLIDATION GLOBALE — FY27
A6: KPIs GLOBAUX
A7: Score Moyen | B7: NC Maj | C7: NC Min | D7: Obs | E7: OFI | F7: BP | G7: TOTAL
A8: =IFERROR(AVERAGE('CDG Sécurité'!B10,RAM!A10,'Min. Intérieur'!A10,'CDG Capital'!A10,AtlanticRe!A10,'Client A'!A10,Servier!A10,MEN!A10,ADM!A10,'CDG DC'!A10,'CDG ITOC'!A10,BPOST!A10,'Graphtalk AIA'!A10,'ONCF APPS'!A10,'ONCF MW'!A10,ANEF!A10,Carrefour!A10,'Vinci Construction'!A10,AXA!A10,OCP!A10),0) -> 1.366014 | B8: ='CDG Sécurité'!D10+RAM!C10+'Min. Intérieur'!C10+'CDG Capital'!C10+AtlanticRe!C10+'Client A'!C10+Servier!C10+MEN!C10+ADM!C10+'CDG DC'!C10+'CDG ITOC'!C10+BPOST!C10+'Graphtalk AIA'!C10+'ONCF APPS'!C10+'ONCF MW'!C10+ANEF!C10+Carrefour!C10+'Vinci Construction'!C10+AXA!C10+OCP!C10 -> 1 | C8: ='CDG Sécurité'!E10+RAM!D10+'Min. Intérieur'!D10+'CDG Capital'!D10+AtlanticRe!D10+'Client A'!D10+Servier!D10+MEN!D10+ADM!D10+'CDG DC'!D10+'CDG ITOC'!D10+BPOST!D10+'Graphtalk AIA'!D10+'ONCF APPS'!D10+'ONCF MW'!D10+ANEF!D10+Carrefour!D10+'Vinci Construction'!D10+AXA!D10+OCP!D10 -> 44 | D8: ='CDG Sécurité'!F10+RAM!E10+'Min. Intérieur'!E10+'CDG Capital'!E10+AtlanticRe!E10+'Client A'!E10+Servier!E10+MEN!E10+ADM!E10+'CDG DC'!E10+'CDG ITOC'!E10+BPOST!E10+'Graphtalk AIA'!E10+'ONCF APPS'!E10+'ONCF MW'!E10+ANEF!E10+Carrefour!E10+'Vinci Construction'!E10+AXA!E10+OCP!E10 -> 6 | E8: ='CDG Sécurité'!G10+RAM!F10+'Min. Intérieur'!F10+'CDG Capital'!F10+AtlanticRe!F10+'Client A'!F10+Servier!F10+MEN!F10+ADM!F10+'CDG DC'!F10+'CDG ITOC'!F10+BPOST!F10+'Graphtalk AIA'!F10+'ONCF APPS'!F10+'ONCF MW'!F10+ANEF!F10+Carrefour!F10+'Vinci Construction'!F10+AXA!F10+OCP!F10 -> 0 | F8: ='CDG Sécurité'!H10+RAM!G10+'Min. Intérieur'!G10+'CDG Capital'!G10+AtlanticRe!G10+'Client A'!G10+Servier!G10+MEN!G10+ADM!G10+'CDG DC'!G10+'CDG ITOC'!G10+BPOST!G10+'Graphtalk AIA'!G10+'ONCF APPS'!G10+'ONCF MW'!G10+ANEF!G10+Carrefour!G10+'Vinci Construction'!G10+AXA!G10+OCP!G10 -> 7 | G8: =B8+C8+D8+E8 -> 51
A10: SYNTHÈSE PAR COMPTE
A11: N° | B11: Compte | C11: Score | D11: Badge | E11: NC Maj | F11: NC Min | G11: Obs | H11: OFI | I11: BP | J11: Total | K11: % NC | L11: Priorité
A12: 1 | B12: CDG Sécurité | C12: ='CDG Sécurité'!B10 -> 2.3636364 | D12: ='DASHBOARD AUDITS'!J12 -> À Risque | E12: ='CDG Sécurité'!D10 -> 1 | F12: ='CDG Sécurité'!E10 -> 5 | G12: ='CDG Sécurité'!F10 -> 1 | H12: ='CDG Sécurité'!G10 -> 0 | I12: ='CDG Sécurité'!H10 -> 0 | J12: =E12+F12+G12+H12 -> 7 | K12: =IFERROR((E12+F12)/J12,0) -> 0.85714286 | L12: =IF(E12>0,"🔴 Critique",IF(J12>5,"🟠 Élevée",IF(J12>2,"🟡 Modérée","🟢 Faible"))) -> 🔴 Critique
A13: 2 | B13: RAM | C13: =RAM!A10 -> 3.1538462 | D13: ='DASHBOARD AUDITS'!J13 -> A Surveiller | E13: =RAM!C10 -> 0 | F13: =RAM!D10 -> 4 | G13: =RAM!E10 -> 1 | H13: =RAM!F10 -> 0 | I13: =RAM!G10 -> 1 | J13: =E13+F13+G13+H13 -> 5 | K13: =IFERROR((E13+F13)/J13,0) -> 0.8 | L13: =IF(E13>0,"🔴 Critique",IF(J13>5,"🟠 Élevée",IF(J13>2,"🟡 Modérée","🟢 Faible"))) -> 🟡 Modérée
A14: 3 | B14: Min. Intérieur | C14: ='Min. Intérieur'!A10 -> 3.3636364 | D14: ='DASHBOARD AUDITS'!J14 -> A Surveiller | E14: ='Min. Intérieur'!C10 -> 0 | F14: ='Min. Intérieur'!D10 -> 7 | G14: ='Min. Intérieur'!E10 -> 0 | H14: ='Min. Intérieur'!F10 -> 0 | I14: ='Min. Intérieur'!G10 -> 2 | J14: =E14+F14+G14+H14 -> 7 | K14: =IFERROR((E14+F14)/J14,0) -> 1 | L14: =IF(E14>0,"🔴 Critique",IF(J14>5,"🟠 Élevée",IF(J14>2,"🟡 Modérée","🟢 Faible"))) -> 🟠 Élevée
A15: 4 | B15: CDG Capital | C15: ='CDG Capital'!A10 -> 2.4545455 | D15: ='DASHBOARD AUDITS'!J15 -> À Risque | E15: ='CDG Capital'!C10 -> 0 | F15: ='CDG Capital'!D10 -> 5 | G15: ='CDG Capital'!E10 -> 2 | H15: ='CDG Capital'!F10 -> 0 | I15: ='CDG Capital'!G10 -> 0 | J15: =E15+F15+G15+H15 -> 7 | K15: =IFERROR((E15+F15)/J15,0) -> 0.71428571 | L15: =IF(E15>0,"🔴 Critique",IF(J15>5,"🟠 Élevée",IF(J15>2,"🟡 Modérée","🟢 Faible"))) -> 🟠 Élevée
A16: 5 | B16: AtlanticRe | C16: =AtlanticRe!A10 -> 2.9615385 | D16: ='DASHBOARD AUDITS'!J16 -> A Surveiller | E16: =AtlanticRe!C10 -> 0 | F16: =AtlanticRe!D10 -> 5 | G16: =AtlanticRe!E10 -> 0 | H16: =AtlanticRe!F10 -> 0 | I16: =AtlanticRe!G10 -> 2 | J16: =E16+F16+G16+H16 -> 5 | K16: =IFERROR((E16+F16)/J16,0) -> 1 | L16: =IF(E16>0,"🔴 Critique",IF(J16>5,"🟠 Élevée",IF(J16>2,"🟡 Modérée","🟢 Faible"))) -> 🟡 Modérée
A17: 6 | B17: Client A | C17: ='Client A'!A10 -> 0 | D17: ='DASHBOARD AUDITS'!J17 -> ⏳ Non audité | E17: ='Client A'!C10 -> 0 | F17: ='Client A'!D10 -> 0 | G17: ='Client A'!E10 -> 0 | H17: ='Client A'!F10 -> 0 | I17: ='Client A'!G10 -> 0 | J17: =E17+F17+G17+H17 -> 0 | K17: =IFERROR((E17+F17)/J17,0) -> 0 | L17: =IF(E17>0,"🔴 Critique",IF(J17>5,"🟠 Élevée",IF(J17>2,"🟡 Modérée","🟢 Faible"))) -> 🟢 Faible
A18: 7 | B18: Servier | C18: =Servier!A10 -> 3.6 | D18: ='DASHBOARD AUDITS'!J18 -> Performant | E18: =Servier!C10 -> 0 | F18: =Servier!D10 -> 4 | G18: =Servier!E10 -> 0 | H18: =Servier!F10 -> 0 | I18: =Servier!G10 -> 0 | J18: =E18+F18+G18+H18 -> 4 | K18: =IFERROR((E18+F18)/J18,0) -> 1 | L18: =IF(E18>0,"🔴 Critique",IF(J18>5,"🟠 Élevée",IF(J18>2,"🟡 Modérée","🟢 Faible"))) -> 🟡 Modérée
A19: 8 | B19: MEN | C19: =MEN!A10 -> 3.1538462 | D19: ='DASHBOARD AUDITS'!J19 -> A Surveiller | E19: =MEN!C10 -> 0 | F19: =MEN!D10 -> 5 | G19: =MEN!E10 -> 0 | H19: =MEN!F10 -> 0 | I19: =MEN!G10 -> 1 | J19: =E19+F19+G19+H19 -> 5 | K19: =IFERROR((E19+F19)/J19,0) -> 1 | L19: =IF(E19>0,"🔴 Critique",IF(J19>5,"🟠 Élevée",IF(J19>2,"🟡 Modérée","🟢 Faible"))) -> 🟡 Modérée
A20: 9 | B20: ADM | C20: =ADM!A10 -> 0 | D20: ='DASHBOARD AUDITS'!J20 -> ⏳ Non audité | E20: =ADM!C10 -> 0 | F20: =ADM!D10 -> 0 | G20: =ADM!E10 -> 0 | H20: =ADM!F10 -> 0 | I20: =ADM!G10 -> 0 | J20: =E20+F20+G20+H20 -> 0 | K20: =IFERROR((E20+F20)/J20,0) -> 0 | L20: =IF(E20>0,"🔴 Critique",IF(J20>5,"🟠 Élevée",IF(J20>2,"🟡 Modérée","🟢 Faible"))) -> 🟢 Faible
A21: 10 | B21: CDG DC | C21: ='CDG DC'!A10 -> 0 | D21: ='DASHBOARD AUDITS'!J21 -> ⏳ Non audité | E21: ='CDG DC'!C10 -> 0 | F21: ='CDG DC'!D10 -> 0 | G21: ='CDG DC'!E10 -> 0 | H21: ='CDG DC'!F10 -> 0 | I21: ='CDG DC'!G10 -> 0 | J21: =E21+F21+G21+H21 -> 0 | K21: =IFERROR((E21+F21)/J21,0) -> 0 | L21: =IF(E21>0,"🔴 Critique",IF(J21>5,"🟠 Élevée",IF(J21>2,"🟡 Modérée","🟢 Faible"))) -> 🟢 Faible
A22: 11 | B22: CDG ITOC | C22: ='CDG ITOC'!A10 -> 0 | D22: ='DASHBOARD AUDITS'!J22 -> ⏳ Non audité | E22: ='CDG ITOC'!C10 -> 0 | F22: ='CDG ITOC'!D10 -> 0 | G22: ='CDG ITOC'!E10 -> 0 | H22: ='CDG ITOC'!F10 -> 0 | I22: ='CDG ITOC'!G10 -> 0 | J22: =E22+F22+G22+H22 -> 0 | K22: =IFERROR((E22+F22)/J22,0) -> 0 | L22: =IF(E22>0,"🔴 Critique",IF(J22>5,"🟠 Élevée",IF(J22>2,"🟡 Modérée","🟢 Faible"))) -> 🟢 Faible
A23: 12 | B23: BPOST | C23: =BPOST!A10 -> 0 | D23: ='DASHBOARD AUDITS'!J23 -> ⏳ Non audité | E23: =BPOST!C10 -> 0 | F23: =BPOST!D10 -> 0 | G23: =BPOST!E10 -> 0 | H23: =BPOST!F10 -> 0 | I23: =BPOST!G10 -> 0 | J23: =E23+F23+G23+H23 -> 0 | K23: =IFERROR((E23+F23)/J23,0) -> 0 | L23: =IF(E23>0,"🔴 Critique",IF(J23>5,"🟠 Élevée",IF(J23>2,"🟡 Modérée","🟢 Faible"))) -> 🟢 Faible
A24: 13 | B24: Graphtalk AIA | C24: ='Graphtalk AIA'!A10 -> 0 | D24: ='DASHBOARD AUDITS'!J24 -> ⏳ Non audité | E24: ='Graphtalk AIA'!C10 -> 0 | F24: ='Graphtalk AIA'!D10 -> 0 | G24: ='Graphtalk AIA'!E10 -> 0 | H24: ='Graphtalk AIA'!F10 -> 0 | I24: ='Graphtalk AIA'!G10 -> 0 | J24: =E24+F24+G24+H24 -> 0 | K24: =IFERROR((E24+F24)/J24,0) -> 0 | L24: =IF(E24>0,"🔴 Critique",IF(J24>5,"🟠 Élevée",IF(J24>2,"🟡 Modérée","🟢 Faible"))) -> 🟢 Faible
A25: 14 | B25: ONCF APPS | C25: ='ONCF APPS'!A10 -> 0 | D25: ='DASHBOARD AUDITS'!J25 -> ⏳ Non audité | E25: ='ONCF APPS'!C10 -> 0 | F25: ='ONCF APPS'!D10 -> 0 | G25: ='ONCF APPS'!E10 -> 0 | H25: ='ONCF APPS'!F10 -> 0 | I25: ='ONCF APPS'!G10 -> 0 | J25: =E25+F25+G25+H25 -> 0 | K25: =IFERROR((E25+F25)/J25,0) -> 0 | L25: =IF(E25>0,"🔴 Critique",IF(J25>5,"🟠 Élevée",IF(J25>2,"🟡 Modérée","🟢 Faible"))) -> 🟢 Faible
A26: 15 | B26: ONCF MW | C26: ='ONCF MW'!A10 -> 3.1153846 | D26: ='DASHBOARD AUDITS'!J26 -> A Surveiller | E26: ='ONCF MW'!C10 -> 0 | F26: ='ONCF MW'!D10 -> 4 | G26: ='ONCF MW'!E10 -> 2 | H26: ='ONCF MW'!F10 -> 0 | I26: ='ONCF MW'!G10 -> 0 | J26: =E26+F26+G26+H26 -> 6 | K26: =IFERROR((E26+F26)/J26,0) -> 0.66666667 | L26: =IF(E26>0,"🔴 Critique",IF(J26>5,"🟠 Élevée",IF(J26>2,"🟡 Modérée","🟢 Faible"))) -> 🟠 Élevée
A27: 16 | B27: ANEF | C27: =ANEF!A10 -> 0 | D27: ='DASHBOARD AUDITS'!J27 -> ⏳ Non audité | E27: =ANEF!C10 -> 0 | F27: =ANEF!D10 -> 0 | G27: =ANEF!E10 -> 0 | H27: =ANEF!F10 -> 0 | I27: =ANEF!G10 -> 0 | J27: =E27+F27+G27+H27 -> 0 | K27: =IFERROR((E27+F27)/J27,0) -> 0 | L27: =IF(E27>0,"🔴 Critique",IF(J27>5,"🟠 Élevée",IF(J27>2,"🟡 Modérée","🟢 Faible"))) -> 🟢 Faible
A28: 17 | B28: Carrefour | C28: =Carrefour!A10 -> 0 | D28: ='DASHBOARD AUDITS'!J28 -> ⏳ Non audité | E28: =Carrefour!C10 -> 0 | F28: =Carrefour!D10 -> 0 | G28: =Carrefour!E10 -> 0 | H28: =Carrefour!F10 -> 0 | I28: =Carrefour!G10 -> 0 | J28: =E28+F28+G28+H28 -> 0 | K28: =IFERROR((E28+F28)/J28,0) -> 0 | L28: =IF(E28>0,"🔴 Critique",IF(J28>5,"🟠 Élevée",IF(J28>2,"🟡 Modérée","🟢 Faible"))) -> 🟢 Faible
A29: 18 | B29: Vinci Construction | C29: ='Vinci Construction'!A10 -> 0 | D29: ='DASHBOARD AUDITS'!J29 -> ⏳ Non audité | E29: ='Vinci Construction'!C10 -> 0 | F29: ='Vinci Construction'!D10 -> 0 | G29: ='Vinci Construction'!E10 -> 0 | H29: ='Vinci Construction'!F10 -> 0 | I29: ='Vinci Construction'!G10 -> 0 | J29: =E29+F29+G29+H29 -> 0 | K29: =IFERROR((E29+F29)/J29,0) -> 0 | L29: =IF(E29>0,"🔴 Critique",IF(J29>5,"🟠 Élevée",IF(J29>2,"🟡 Modérée","🟢 Faible"))) -> 🟢 Faible
A30: 19 | B30: AXA | C30: =AXA!A10 -> 0 | D30: ='DASHBOARD AUDITS'!J30 -> ⏳ Non audité | E30: =AXA!C10 -> 0 | F30: =AXA!D10 -> 0 | G30: =AXA!E10 -> 0 | H30: =AXA!F10 -> 0 | I30: =AXA!G10 -> 0 | J30: =E30+F30+G30+H30 -> 0 | K30: =IFERROR((E30+F30)/J30,0) -> 0 | L30: =IF(E30>0,"🔴 Critique",IF(J30>5,"🟠 Élevée",IF(J30>2,"🟡 Modérée","🟢 Faible"))) -> 🟢 Faible
A31: 20 | B31: OCP | C31: =OCP!A10 -> 3.1538462 | D31: ='DASHBOARD AUDITS'!J31 -> A Surveiller | E31: =OCP!C10 -> 0 | F31: =OCP!D10 -> 5 | G31: =OCP!E10 -> 0 | H31: =OCP!F10 -> 0 | I31: =OCP!G10 -> 1 | J31: =E31+F31+G31+H31 -> 5 | K31: =IFERROR((E31+F31)/J31,0) -> 1 | L31: =IF(E31>0,"🔴 Critique",IF(J31>5,"🟠 Élevée",IF(J31>2,"🟡 Modérée","🟢 Faible"))) -> 🟡 Modérée
A34: HEATMAP MATURITÉ PAR CHAPITRE
A35: Ch | B35: Libellé | C35: CDG Sé | D35: RAM | E35: Min. I | F35: CDG Ca | G35: Atlant | H35: Client A | I35: Servier | J35: MEN | K35: ADM | L35: CDG DC | M35: CDG IT | N35: BPOST | O35: Grapht | P35: ONCF A | Q35: OCP MW | R35: ANEF | S35: Carref | T35: Vinci | U35: AXA | V35: OCP | W35: Moy.
A36: Ch4 | B36: Contexte | C36: ='CDG Sécurité'!E55 -> 1 | D36: =RAM!D55 -> 3 | E36: ='Min. Intérieur'!D55 -> 2 | F36: ='CDG Capital'!D55 -> 1 | G36: =AtlanticRe!D55 -> 3 | H36: ='Client A'!D55 -> 0 | I36: =Servier!D55 -> 2.5 | J36: =MEN!D55 -> 3.5 | K36: =ADM!D55 -> 0 | L36: ='CDG DC'!D55 -> 0 | M36: ='CDG ITOC'!D55 -> 0 | N36: =BPOST!D55 -> 0 | O36: ='Graphtalk AIA'!D55 -> 0 | P36: ='ONCF APPS'!D55 -> 0 | Q36: ='ONCF MW'!D55 -> 3 | R36: =ANEF!D55 -> 0 | S36: =Carrefour!D55 -> 0 | T36: ='Vinci Construction'!D55 -> 0 | U36: =AXA!D55 -> 0 | V36: =OCP!D55 -> 3.5 | W36: =IFERROR(AVERAGE(C36:V36),0) -> 1.125
A37: Ch5 | B37: Leadership | C37: ='CDG Sécurité'!E56 -> 3 | D37: =RAM!D56 -> 3.5 | E37: ='Min. Intérieur'!D56 -> 4 | F37: ='CDG Capital'!D56 -> 0 | G37: =AtlanticRe!D56 -> 3.5 | H37: ='Client A'!D56 -> 0 | I37: =Servier!D56 -> 3 | J37: =MEN!D56 -> 3.5 | K37: =ADM!D56 -> 0 | L37: ='CDG DC'!D56 -> 0 | M37: ='CDG ITOC'!D56 -> 0 | N37: =BPOST!D56 -> 0 | O37: ='Graphtalk AIA'!D56 -> 0 | P37: ='ONCF APPS'!D56 -> 0 | Q37: ='ONCF MW'!D56 -> 3.5 | R37: =ANEF!D56 -> 0 | S37: =Carrefour!D56 -> 0 | T37: ='Vinci Construction'!D56 -> 0 | U37: =AXA!D56 -> 0 | V37: =OCP!D56 -> 3.5 | W37: =IFERROR(AVERAGE(C37:V37),0) -> 1.375
A38: Ch6 | B38: Planification | C38: ='CDG Sécurité'!E57 -> 2.3333333 | D38: =RAM!D57 -> 2.6666667 | E38: ='Min. Intérieur'!D57 -> 2 | F38: ='CDG Capital'!D57 -> 0 | G38: =AtlanticRe!D57 -> 2.6666667 | H38: ='Client A'!D57 -> 0 | I38: =Servier!D57 -> 3.5 | J38: =MEN!D57 -> 2.6666667 | K38: =ADM!D57 -> 0 | L38: ='CDG DC'!D57 -> 0 | M38: ='CDG ITOC'!D57 -> 0 | N38: =BPOST!D57 -> 0 | O38: ='Graphtalk AIA'!D57 -> 0 | P38: ='ONCF APPS'!D57 -> 0 | Q38: ='ONCF MW'!D57 -> 3 | R38: =ANEF!D57 -> 0 | S38: =Carrefour!D57 -> 0 | T38: ='Vinci Construction'!D57 -> 0 | U38: =AXA!D57 -> 0 | V38: =OCP!D57 -> 2.6666667 | W38: =IFERROR(AVERAGE(C38:V38),0) -> 1.075
A39: Ch7 | B39: Support | C39: ='CDG Sécurité'!E58 -> 2.3333333 | D39: =RAM!D58 -> 2 | E39: ='Min. Intérieur'!D58 -> 2 | F39: ='CDG Capital'!D58 -> 0 | G39: =AtlanticRe!D58 -> 2 | H39: ='Client A'!D58 -> 0 | I39: =Servier!D58 -> 3.6666667 | J39: =MEN!D58 -> 2.75 | K39: =ADM!D58 -> 0 | L39: ='CDG DC'!D58 -> 0 | M39: ='CDG ITOC'!D58 -> 0 | N39: =BPOST!D58 -> 0 | O39: ='Graphtalk AIA'!D58 -> 0 | P39: ='ONCF APPS'!D58 -> 0 | Q39: ='ONCF MW'!D58 -> 2.75 | R39: =ANEF!D58 -> 0 | S39: =Carrefour!D58 -> 0 | T39: ='Vinci Construction'!D58 -> 0 | U39: =AXA!D58 -> 0 | V39: =OCP!D58 -> 2.75 | W39: =IFERROR(AVERAGE(C39:V39),0) -> 1.0125
A40: Ch8 | B40: Réalisation | C40: ='CDG Sécurité'!E59 -> 0 | D40: =RAM!D59 -> 3.4 | E40: ='Min. Intérieur'!D59 -> 4 | F40: ='CDG Capital'!D59 -> 0 | G40: =AtlanticRe!D59 -> 3.1 | H40: ='Client A'!D59 -> 0 | I40: =Servier!D59 -> 3.3333333 | J40: =MEN!D59 -> 3.2 | K40: =ADM!D59 -> 0 | L40: ='CDG DC'!D59 -> 0 | M40: ='CDG ITOC'!D59 -> 0 | N40: =BPOST!D59 -> 0 | O40: ='Graphtalk AIA'!D59 -> 0 | P40: ='ONCF APPS'!D59 -> 0 | Q40: ='ONCF MW'!D59 -> 3.2 | R40: =ANEF!D59 -> 0 | S40: =Carrefour!D59 -> 0 | T40: ='Vinci Construction'!D59 -> 0 | U40: =AXA!D59 -> 0 | V40: =OCP!D59 -> 3.2 | W40: =IFERROR(AVERAGE(C40:V40),0) -> 1.1716667
A41: Ch9 | B41: Performance | C41: ='CDG Sécurité'!E60 -> 0 | D41: =RAM!D60 -> 3.6666667 | E41: ='Min. Intérieur'!D60 -> 4 | F41: ='CDG Capital'!D60 -> 0 | G41: =AtlanticRe!D60 -> 3.5 | H41: ='Client A'!D60 -> 0 | I41: =Servier!D60 -> 3.5 | J41: =MEN!D60 -> 3.6666667 | K41: =ADM!D60 -> 0 | L41: ='CDG DC'!D60 -> 0 | M41: ='CDG ITOC'!D60 -> 0 | N41: =BPOST!D60 -> 0 | O41: ='Graphtalk AIA'!D60 -> 0 | P41: ='ONCF APPS'!D60 -> 0 | Q41: ='ONCF MW'!D60 -> 3.3333333 | R41: =ANEF!D60 -> 0 | S41: =Carrefour!D60 -> 0 | T41: ='Vinci Construction'!D60 -> 0 | U41: =AXA!D60 -> 0 | V41: =OCP!D60 -> 3.6666667 | W41: =IFERROR(AVERAGE(C41:V41),0) -> 1.2666667
A42: Ch10 | B42: Amélioration | C42: ='CDG Sécurité'!E61 -> 0 | D42: =RAM!D61 -> 4 | E42: ='Min. Intérieur'!D61 -> 4 | F42: ='CDG Capital'!D61 -> 0 | G42: =AtlanticRe!D61 -> 3 | H42: ='Client A'!D61 -> 0 | I42: =Servier!D61 -> 3 | J42: =MEN!D61 -> 3 | K42: =ADM!D61 -> 0 | L42: ='CDG DC'!D61 -> 0 | M42: ='CDG ITOC'!D61 -> 0 | N42: =BPOST!D61 -> 0 | O42: ='Graphtalk AIA'!D61 -> 0 | P42: ='ONCF APPS'!D61 -> 0 | Q42: ='ONCF MW'!D61 -> 3 | R42: =ANEF!D61 -> 0 | S42: =Carrefour!D61 -> 0 | T42: ='Vinci Construction'!D61 -> 0 | U42: =AXA!D61 -> 0 | V42: =OCP!D61 -> 3 | W42: =IFERROR(AVERAGE(C42:V42),0) -> 1.15

Sheet ANALYSE FINDINGS
A1: ANALYSE DES FINDINGS PAR LIBELLÉ TERRAIN — FY27
A3: 1. NOMBRE DE FINDINGS PAR LIBELLÉ TERRAIN (GLOBAL)
A5: N° | B5: Clause | C5: Libellé Terrain | D5: NC Maj | E5: NC Min | F5: Obs | G5: OFI | H5: Total | I5: % Total | J5: Criticité
A6: 1 | B6: 4.1 | C6: Connaissance de notre environnement | D6: =COUNTIF('CDG Sécurité'!K15,"NC Majeure")+COUNTIF(RAM!J15,"NC Majeure")+COUNTIF('Min. Intérieur'!J15,"NC Majeure")+COUNTIF('CDG Capital'!J15,"NC Majeure")+COUNTIF(AtlanticRe!J15,"NC Majeure")+COUNTIF('Client A'!J15,"NC Majeure")+COUNTIF(Servier!J15,"NC Majeure")+COUNTIF(MEN!J15,"NC Majeure")+COUNTIF(ADM!J15,"NC Majeure")+COUNTIF('CDG DC'!J15,"NC Majeure")+COUNTIF('CDG ITOC'!J15,"NC Majeure")+COUNTIF(BPOST!J15,"NC Majeure")+COUNTIF('Graphtalk AIA'!J15,"NC Majeure")+COUNTIF('ONCF APPS'!J15,"NC Majeure")+COUNTIF('ONCF MW'!J15,"NC Majeure")+COUNTIF(ANEF!J15,"NC Majeure")+COUNTIF(Carrefour!J15,"NC Majeure")+COUNTIF('Vinci Construction'!J15,"NC Majeure")+COUNTIF(AXA!J15,"NC Majeure")+COUNTIF(OCP!J15,"NC Majeure") -> 1 | E6: =COUNTIF('CDG Sécurité'!K15,"NC Mineure")+COUNTIF(RAM!J15,"NC Mineure")+COUNTIF('Min. Intérieur'!J15,"NC Mineure")+COUNTIF('CDG Capital'!J15,"NC Mineure")+COUNTIF(AtlanticRe!J15,"NC Mineure")+COUNTIF('Client A'!J15,"NC Mineure")+COUNTIF(Servier!J15,"NC Mineure")+COUNTIF(MEN!J15,"NC Mineure")+COUNTIF(ADM!J15,"NC Mineure")+COUNTIF('CDG DC'!J15,"NC Mineure")+COUNTIF('CDG ITOC'!J15,"NC Mineure")+COUNTIF(BPOST!J15,"NC Mineure")+COUNTIF('Graphtalk AIA'!J15,"NC Mineure")+COUNTIF('ONCF APPS'!J15,"NC Mineure")+COUNTIF('ONCF MW'!J15,"NC Mineure")+COUNTIF(ANEF!J15,"NC Mineure")+COUNTIF(Carrefour!J15,"NC Mineure")+COUNTIF('Vinci Construction'!J15,"NC Mineure")+COUNTIF(AXA!J15,"NC Mineure")+COUNTIF(OCP!J15,"NC Mineure") -> 7 | F6: =COUNTIF('CDG Sécurité'!K15,"Observation")+COUNTIF(RAM!J15,"Observation")+COUNTIF('Min. Intérieur'!J15,"Observation")+COUNTIF('CDG Capital'!J15,"Observation")+COUNTIF(AtlanticRe!J15,"Observation")+COUNTIF('Client A'!J15,"Observation")+COUNTIF(Servier!J15,"Observation")+COUNTIF(MEN!J15,"Observation")+COUNTIF(ADM!J15,"Observation")+COUNTIF('CDG DC'!J15,"Observation")+COUNTIF('CDG ITOC'!J15,"Observation")+COUNTIF(BPOST!J15,"Observation")+COUNTIF('Graphtalk AIA'!J15,"Observation")+COUNTIF('ONCF APPS'!J15,"Observation")+COUNTIF('ONCF MW'!J15,"Observation")+COUNTIF(ANEF!J15,"Observation")+COUNTIF(Carrefour!J15,"Observation")+COUNTIF('Vinci Construction'!J15,"Observation")+COUNTIF(AXA!J15,"Observation")+COUNTIF(OCP!J15,"Observation") -> 1 | G6: =COUNTIF('CDG Sécurité'!K15,"OFI")+COUNTIF(RAM!J15,"OFI")+COUNTIF('Min. Intérieur'!J15,"OFI")+COUNTIF('CDG Capital'!J15,"OFI")+COUNTIF(AtlanticRe!J15,"OFI")+COUNTIF('Client A'!J15,"OFI")+COUNTIF(Servier!J15,"OFI")+COUNTIF(MEN!J15,"OFI")+COUNTIF(ADM!J15,"OFI")+COUNTIF('CDG DC'!J15,"OFI")+COUNTIF('CDG ITOC'!J15,"OFI")+COUNTIF(BPOST!J15,"OFI")+COUNTIF('Graphtalk AIA'!J15,"OFI")+COUNTIF('ONCF APPS'!J15,"OFI")+COUNTIF('ONCF MW'!J15,"OFI")+COUNTIF(ANEF!J15,"OFI")+COUNTIF(Carrefour!J15,"OFI")+COUNTIF('Vinci Construction'!J15,"OFI")+COUNTIF(AXA!J15,"OFI")+COUNTIF(OCP!J15,"OFI") -> 0 | H6: =D6+E6+F6+G6 -> 9 | I6: =IFERROR(H6/H43,0) -> 0.17647059 | J6: =IF(D6>0,"🔴 Critique",IF(H6>5,"🟠 Fort",IF(H6>2,"🟡 Modéré",IF(H6>0,"🔵 Faible","✅ Aucun")))) -> 🔴 Critique
A7: 2 | B7: 4.2 | C7: Écoute des parties prenantes | D7: =COUNTIF('CDG Sécurité'!K16,"NC Majeure")+COUNTIF(RAM!J16,"NC Majeure")+COUNTIF('Min. Intérieur'!J16,"NC Majeure")+COUNTIF('CDG Capital'!J18,"NC Majeure")+COUNTIF(AtlanticRe!J16,"NC Majeure")+COUNTIF('Client A'!J16,"NC Majeure")+COUNTIF(Servier!J16,"NC Majeure")+COUNTIF(MEN!J16,"NC Majeure")+COUNTIF(ADM!J16,"NC Majeure")+COUNTIF('CDG DC'!J16,"NC Majeure")+COUNTIF('CDG ITOC'!J16,"NC Majeure")+COUNTIF(BPOST!J16,"NC Majeure")+COUNTIF('Graphtalk AIA'!J16,"NC Majeure")+COUNTIF('ONCF APPS'!J16,"NC Majeure")+COUNTIF('ONCF MW'!J16,"NC Majeure")+COUNTIF(ANEF!J16,"NC Majeure")+COUNTIF(Carrefour!J16,"NC Majeure")+COUNTIF('Vinci Construction'!J16,"NC Majeure")+COUNTIF(AXA!J16,"NC Majeure")+COUNTIF(OCP!J16,"NC Majeure") -> 0 | E7: =COUNTIF('CDG Sécurité'!K16,"NC Mineure")+COUNTIF(RAM!J16,"NC Mineure")+COUNTIF('Min. Intérieur'!J16,"NC Mineure")+COUNTIF('CDG Capital'!J18,"NC Mineure")+COUNTIF(AtlanticRe!J16,"NC Mineure")+COUNTIF('Client A'!J16,"NC Mineure")+COUNTIF(Servier!J16,"NC Mineure")+COUNTIF(MEN!J16,"NC Mineure")+COUNTIF(ADM!J16,"NC Mineure")+COUNTIF('CDG DC'!J16,"NC Mineure")+COUNTIF('CDG ITOC'!J16,"NC Mineure")+COUNTIF(BPOST!J16,"NC Mineure")+COUNTIF('Graphtalk AIA'!J16,"NC Mineure")+COUNTIF('ONCF APPS'!J16,"NC Mineure")+COUNTIF('ONCF MW'!J16,"NC Mineure")+COUNTIF(ANEF!J16,"NC Mineure")+COUNTIF(Carrefour!J16,"NC Mineure")+COUNTIF('Vinci Construction'!J16,"NC Mineure")+COUNTIF(AXA!J16,"NC Mineure")+COUNTIF(OCP!J16,"NC Mineure") -> 1 | F7: =COUNTIF('CDG Sécurité'!K16,"Observation")+COUNTIF(RAM!J16,"Observation")+COUNTIF('Min. Intérieur'!J16,"Observation")+COUNTIF('CDG Capital'!J18,"Observation")+COUNTIF(AtlanticRe!J16,"Observation")+COUNTIF('Client A'!J16,"Observation")+COUNTIF(Servier!J16,"Observation")+COUNTIF(MEN!J16,"Observation")+COUNTIF(ADM!J16,"Observation")+COUNTIF('CDG DC'!J16,"Observation")+COUNTIF('CDG ITOC'!J16,"Observation")+COUNTIF(BPOST!J16,"Observation")+COUNTIF('Graphtalk AIA'!J16,"Observation")+COUNTIF('ONCF APPS'!J16,"Observation")+COUNTIF('ONCF MW'!J16,"Observation")+COUNTIF(ANEF!J16,"Observation")+COUNTIF(Carrefour!J16,"Observation")+COUNTIF('Vinci Construction'!J16,"Observation")+COUNTIF(AXA!J16,"Observation")+COUNTIF(OCP!J16,"Observation") -> 0 | G7: =COUNTIF('CDG Sécurité'!K16,"OFI")+COUNTIF(RAM!J16,"OFI")+COUNTIF('Min. Intérieur'!J16,"OFI")+COUNTIF('CDG Capital'!J18,"OFI")+COUNTIF(AtlanticRe!J16,"OFI")+COUNTIF('Client A'!J16,"OFI")+COUNTIF(Servier!J16,"OFI")+COUNTIF(MEN!J16,"OFI")+COUNTIF(ADM!J16,"OFI")+COUNTIF('CDG DC'!J16,"OFI")+COUNTIF('CDG ITOC'!J16,"OFI")+COUNTIF(BPOST!J16,"OFI")+COUNTIF('Graphtalk AIA'!J16,"OFI")+COUNTIF('ONCF APPS'!J16,"OFI")+COUNTIF('ONCF MW'!J16,"OFI")+COUNTIF(ANEF!J16,"OFI")+COUNTIF(Carrefour!J16,"OFI")+COUNTIF('Vinci Construction'!J16,"OFI")+COUNTIF(AXA!J16,"OFI")+COUNTIF(OCP!J16,"OFI") -> 0 | H7: =D7+E7+F7+G7 -> 1 | I7: =IFERROR(H7/H43,0) -> 0.019607843 | J7: =IF(D7>0,"🔴 Critique",IF(H7>5,"🟠 Fort",IF(H7>2,"🟡 Modéré",IF(H7>0,"🔵 Faible","✅ Aucun")))) -> 🔵 Faible
A8: 3 | B8: 4.3 | C8: Périmètre de notre système qualité | D8: =COUNTIF('CDG Sécurité'!K17,"NC Majeure")+COUNTIF(RAM!J17,"NC Majeure")+COUNTIF('Min. Intérieur'!J17,"NC Majeure")+COUNTIF('CDG Capital'!J20,"NC Majeure")+COUNTIF(AtlanticRe!J17,"NC Majeure")+COUNTIF('Client A'!J17,"NC Majeure")+COUNTIF(Servier!J17,"NC Majeure")+COUNTIF(MEN!J17,"NC Majeure")+COUNTIF(ADM!J17,"NC Majeure")+COUNTIF('CDG DC'!J17,"NC Majeure")+COUNTIF('CDG ITOC'!J17,"NC Majeure")+COUNTIF(BPOST!J17,"NC Majeure")+COUNTIF('Graphtalk AIA'!J17,"NC Majeure")+COUNTIF('ONCF APPS'!J17,"NC Majeure")+COUNTIF('ONCF MW'!J17,"NC Majeure")+COUNTIF(ANEF!J17,"NC Majeure")+COUNTIF(Carrefour!J17,"NC Majeure")+COUNTIF('Vinci Construction'!J17,"NC Majeure")+COUNTIF(AXA!J17,"NC Majeure")+COUNTIF(OCP!J17,"NC Majeure") -> 0 | E8: =COUNTIF('CDG Sécurité'!K17,"NC Mineure")+COUNTIF(RAM!J17,"NC Mineure")+COUNTIF('Min. Intérieur'!J17,"NC Mineure")+COUNTIF('CDG Capital'!J20,"NC Mineure")+COUNTIF(AtlanticRe!J17,"NC Mineure")+COUNTIF('Client A'!J17,"NC Mineure")+COUNTIF(Servier!J17,"NC Mineure")+COUNTIF(MEN!J17,"NC Mineure")+COUNTIF(ADM!J17,"NC Mineure")+COUNTIF('CDG DC'!J17,"NC Mineure")+COUNTIF('CDG ITOC'!J17,"NC Mineure")+COUNTIF(BPOST!J17,"NC Mineure")+COUNTIF('Graphtalk AIA'!J17,"NC Mineure")+COUNTIF('ONCF APPS'!J17,"NC Mineure")+COUNTIF('ONCF MW'!J17,"NC Mineure")+COUNTIF(ANEF!J17,"NC Mineure")+COUNTIF(Carrefour!J17,"NC Mineure")+COUNTIF('Vinci Construction'!J17,"NC Mineure")+COUNTIF(AXA!J17,"NC Mineure")+COUNTIF(OCP!J17,"NC Mineure") -> 0 | F8: =COUNTIF('CDG Sécurité'!K17,"Observation")+COUNTIF(RAM!J17,"Observation")+COUNTIF('Min. Intérieur'!J17,"Observation")+COUNTIF('CDG Capital'!J20,"Observation")+COUNTIF(AtlanticRe!J17,"Observation")+COUNTIF('Client A'!J17,"Observation")+COUNTIF(Servier!J17,"Observation")+COUNTIF(MEN!J17,"Observation")+COUNTIF(ADM!J17,"Observation")+COUNTIF('CDG DC'!J17,"Observation")+COUNTIF('CDG ITOC'!J17,"Observation")+COUNTIF(BPOST!J17,"Observation")+COUNTIF('Graphtalk AIA'!J17,"Observation")+COUNTIF('ONCF APPS'!J17,"Observation")+COUNTIF('ONCF MW'!J17,"Observation")+COUNTIF(ANEF!J17,"Observation")+COUNTIF(Carrefour!J17,"Observation")+COUNTIF('Vinci Construction'!J17,"Observation")+COUNTIF(AXA!J17,"Observation")+COUNTIF(OCP!J17,"Observation") -> 0 | G8: =COUNTIF('CDG Sécurité'!K17,"OFI")+COUNTIF(RAM!J17,"OFI")+COUNTIF('Min. Intérieur'!J17,"OFI")+COUNTIF('CDG Capital'!J20,"OFI")+COUNTIF(AtlanticRe!J17,"OFI")+COUNTIF('Client A'!J17,"OFI")+COUNTIF(Servier!J17,"OFI")+COUNTIF(MEN!J17,"OFI")+COUNTIF(ADM!J17,"OFI")+COUNTIF('CDG DC'!J17,"OFI")+COUNTIF('CDG ITOC'!J17,"OFI")+COUNTIF(BPOST!J17,"OFI")+COUNTIF('Graphtalk AIA'!J17,"OFI")+COUNTIF('ONCF APPS'!J17,"OFI")+COUNTIF('ONCF MW'!J17,"OFI")+COUNTIF(ANEF!J17,"OFI")+COUNTIF(Carrefour!J17,"OFI")+COUNTIF('Vinci Construction'!J17,"OFI")+COUNTIF(AXA!J17,"OFI")+COUNTIF(OCP!J17,"OFI") -> 0 | H8: =D8+E8+F8+G8 -> 0 | I8: =IFERROR(H8/H43,0) -> 0 | J8: =IF(D8>0,"🔴 Critique",IF(H8>5,"🟠 Fort",IF(H8>2,"🟡 Modéré",IF(H8>0,"🔵 Faible","✅ Aucun")))) -> ✅ Aucun
A9: 4 | B9: 4.4 | C9: Cartographie de nos processus | D9: =COUNTIF('CDG Sécurité'!K18,"NC Majeure")+COUNTIF(RAM!J18,"NC Majeure")+COUNTIF('Min. Intérieur'!J18,"NC Majeure")+COUNTIF('CDG Capital'!J21,"NC Majeure")+COUNTIF(AtlanticRe!J18,"NC Majeure")+COUNTIF('Client A'!J18,"NC Majeure")+COUNTIF(Servier!J18,"NC Majeure")+COUNTIF(MEN!J18,"NC Majeure")+COUNTIF(ADM!J18,"NC Majeure")+COUNTIF('CDG DC'!J18,"NC Majeure")+COUNTIF('CDG ITOC'!J18,"NC Majeure")+COUNTIF(BPOST!J18,"NC Majeure")+COUNTIF('Graphtalk AIA'!J18,"NC Majeure")+COUNTIF('ONCF APPS'!J18,"NC Majeure")+COUNTIF('ONCF MW'!J18,"NC Majeure")+COUNTIF(ANEF!J18,"NC Majeure")+COUNTIF(Carrefour!J18,"NC Majeure")+COUNTIF('Vinci Construction'!J18,"NC Majeure")+COUNTIF(AXA!J18,"NC Majeure")+COUNTIF(OCP!J18,"NC Majeure") -> 0 | E9: =COUNTIF('CDG Sécurité'!K18,"NC Mineure")+COUNTIF(RAM!J18,"NC Mineure")+COUNTIF('Min. Intérieur'!J18,"NC Mineure")+COUNTIF('CDG Capital'!J21,"NC Mineure")+COUNTIF(AtlanticRe!J18,"NC Mineure")+COUNTIF('Client A'!J18,"NC Mineure")+COUNTIF(Servier!J18,"NC Mineure")+COUNTIF(MEN!J18,"NC Mineure")+COUNTIF(ADM!J18,"NC Mineure")+COUNTIF('CDG DC'!J18,"NC Mineure")+COUNTIF('CDG ITOC'!J18,"NC Mineure")+COUNTIF(BPOST!J18,"NC Mineure")+COUNTIF('Graphtalk AIA'!J18,"NC Mineure")+COUNTIF('ONCF APPS'!J18,"NC Mineure")+COUNTIF('ONCF MW'!J18,"NC Mineure")+COUNTIF(ANEF!J18,"NC Mineure")+COUNTIF(Carrefour!J18,"NC Mineure")+COUNTIF('Vinci Construction'!J18,"NC Mineure")+COUNTIF(AXA!J18,"NC Mineure")+COUNTIF(OCP!J18,"NC Mineure") -> 1 | F9: =COUNTIF('CDG Sécurité'!K18,"Observation")+COUNTIF(RAM!J18,"Observation")+COUNTIF('Min. Intérieur'!J18,"Observation")+COUNTIF('CDG Capital'!J21,"Observation")+COUNTIF(AtlanticRe!J18,"Observation")+COUNTIF('Client A'!J18,"Observation")+COUNTIF(Servier!J18,"Observation")+COUNTIF(MEN!J18,"Observation")+COUNTIF(ADM!J18,"Observation")+COUNTIF('CDG DC'!J18,"Observation")+COUNTIF('CDG ITOC'!J18,"Observation")+COUNTIF(BPOST!J18,"Observation")+COUNTIF('Graphtalk AIA'!J18,"Observation")+COUNTIF('ONCF APPS'!J18,"Observation")+COUNTIF('ONCF MW'!J18,"Observation")+COUNTIF(ANEF!J18,"Observation")+COUNTIF(Carrefour!J18,"Observation")+COUNTIF('Vinci Construction'!J18,"Observation")+COUNTIF(AXA!J18,"Observation")+COUNTIF(OCP!J18,"Observation") -> 1 | G9: =COUNTIF('CDG Sécurité'!K18,"OFI")+COUNTIF(RAM!J18,"OFI")+COUNTIF('Min. Intérieur'!J18,"OFI")+COUNTIF('CDG Capital'!J21,"OFI")+COUNTIF(AtlanticRe!J18,"OFI")+COUNTIF('Client A'!J18,"OFI")+COUNTIF(Servier!J18,"OFI")+COUNTIF(MEN!J18,"OFI")+COUNTIF(ADM!J18,"OFI")+COUNTIF('CDG DC'!J18,"OFI")+COUNTIF('CDG ITOC'!J18,"OFI")+COUNTIF(BPOST!J18,"OFI")+COUNTIF('Graphtalk AIA'!J18,"OFI")+COUNTIF('ONCF APPS'!J18,"OFI")+COUNTIF('ONCF MW'!J18,"OFI")+COUNTIF(ANEF!J18,"OFI")+COUNTIF(Carrefour!J18,"OFI")+COUNTIF('Vinci Construction'!J18,"OFI")+COUNTIF(AXA!J18,"OFI")+COUNTIF(OCP!J18,"OFI") -> 0 | H9: =D9+E9+F9+G9 -> 2 | I9: =IFERROR(H9/H43,0) -> 0.039215686 | J9: =IF(D9>0,"🔴 Critique",IF(H9>5,"🟠 Fort",IF(H9>2,"🟡 Modéré",IF(H9>0,"🔵 Faible","✅ Aucun")))) -> 🔵 Faible
A10: 5 | B10: 5.1 | C10: Engagement de la direction | D10: =COUNTIF('CDG Sécurité'!K19,"NC Majeure")+COUNTIF(RAM!J19,"NC Majeure")+COUNTIF('Min. Intérieur'!J19,"NC Majeure")+COUNTIF('CDG Capital'!J22,"NC Majeure")+COUNTIF(AtlanticRe!J19,"NC Majeure")+COUNTIF('Client A'!J19,"NC Majeure")+COUNTIF(Servier!J19,"NC Majeure")+COUNTIF(MEN!J19,"NC Majeure")+COUNTIF(ADM!J19,"NC Majeure")+COUNTIF('CDG DC'!J19,"NC Majeure")+COUNTIF('CDG ITOC'!J19,"NC Majeure")+COUNTIF(BPOST!J19,"NC Majeure")+COUNTIF('Graphtalk AIA'!J19,"NC Majeure")+COUNTIF('ONCF APPS'!J19,"NC Majeure")+COUNTIF('ONCF MW'!J19,"NC Majeure")+COUNTIF(ANEF!J19,"NC Majeure")+COUNTIF(Carrefour!J19,"NC Majeure")+COUNTIF('Vinci Construction'!J19,"NC Majeure")+COUNTIF(AXA!J19,"NC Majeure")+COUNTIF(OCP!J19,"NC Majeure") -> 0 | E10: =COUNTIF('CDG Sécurité'!K19,"NC Mineure")+COUNTIF(RAM!J19,"NC Mineure")+COUNTIF('Min. Intérieur'!J19,"NC Mineure")+COUNTIF('CDG Capital'!J22,"NC Mineure")+COUNTIF(AtlanticRe!J19,"NC Mineure")+COUNTIF('Client A'!J19,"NC Mineure")+COUNTIF(Servier!J19,"NC Mineure")+COUNTIF(MEN!J19,"NC Mineure")+COUNTIF(ADM!J19,"NC Mineure")+COUNTIF('CDG DC'!J19,"NC Mineure")+COUNTIF('CDG ITOC'!J19,"NC Mineure")+COUNTIF(BPOST!J19,"NC Mineure")+COUNTIF('Graphtalk AIA'!J19,"NC Mineure")+COUNTIF('ONCF APPS'!J19,"NC Mineure")+COUNTIF('ONCF MW'!J19,"NC Mineure")+COUNTIF(ANEF!J19,"NC Mineure")+COUNTIF(Carrefour!J19,"NC Mineure")+COUNTIF('Vinci Construction'!J19,"NC Mineure")+COUNTIF(AXA!J19,"NC Mineure")+COUNTIF(OCP!J19,"NC Mineure") -> 1 | F10: =COUNTIF('CDG Sécurité'!K19,"Observation")+COUNTIF(RAM!J19,"Observation")+COUNTIF('Min. Intérieur'!J19,"Observation")+COUNTIF('CDG Capital'!J22,"Observation")+COUNTIF(AtlanticRe!J19,"Observation")+COUNTIF('Client A'!J19,"Observation")+COUNTIF(Servier!J19,"Observation")+COUNTIF(MEN!J19,"Observation")+COUNTIF(ADM!J19,"Observation")+COUNTIF('CDG DC'!J19,"Observation")+COUNTIF('CDG ITOC'!J19,"Observation")+COUNTIF(BPOST!J19,"Observation")+COUNTIF('Graphtalk AIA'!J19,"Observation")+COUNTIF('ONCF APPS'!J19,"Observation")+COUNTIF('ONCF MW'!J19,"Observation")+COUNTIF(ANEF!J19,"Observation")+COUNTIF(Carrefour!J19,"Observation")+COUNTIF('Vinci Construction'!J19,"Observation")+COUNTIF(AXA!J19,"Observation")+COUNTIF(OCP!J19,"Observation") -> 0 | G10: =COUNTIF('CDG Sécurité'!K19,"OFI")+COUNTIF(RAM!J19,"OFI")+COUNTIF('Min. Intérieur'!J19,"OFI")+COUNTIF('CDG Capital'!J22,"OFI")+COUNTIF(AtlanticRe!J19,"OFI")+COUNTIF('Client A'!J19,"OFI")+COUNTIF(Servier!J19,"OFI")+COUNTIF(MEN!J19,"OFI")+COUNTIF(ADM!J19,"OFI")+COUNTIF('CDG DC'!J19,"OFI")+COUNTIF('CDG ITOC'!J19,"OFI")+COUNTIF(BPOST!J19,"OFI")+COUNTIF('Graphtalk AIA'!J19,"OFI")+COUNTIF('ONCF APPS'!J19,"OFI")+COUNTIF('ONCF MW'!J19,"OFI")+COUNTIF(ANEF!J19,"OFI")+COUNTIF(Carrefour!J19,"OFI")+COUNTIF('Vinci Construction'!J19,"OFI")+COUNTIF(AXA!J19,"OFI")+COUNTIF(OCP!J19,"OFI") -> 0 | H10: =D10+E10+F10+G10 -> 1 | I10: =IFERROR(H10/H43,0) -> 0.019607843 | J10: =IF(D10>0,"🔴 Critique",IF(H10>5,"🟠 Fort",IF(H10>2,"🟡 Modéré",IF(H10>0,"🔵 Faible","✅ Aucun")))) -> 🔵 Faible
A11: 6 | B11: 5.2 | C11: Notre politique qualité | D11: =COUNTIF('CDG Sécurité'!K20,"NC Majeure")+COUNTIF(RAM!J20,"NC Majeure")+COUNTIF('Min. Intérieur'!J20,"NC Majeure")+COUNTIF('CDG Capital'!J23,"NC Majeure")+COUNTIF(AtlanticRe!J20,"NC Majeure")+COUNTIF('Client A'!J20,"NC Majeure")+COUNTIF(Servier!J20,"NC Majeure")+COUNTIF(MEN!J20,"NC Majeure")+COUNTIF(ADM!J20,"NC Majeure")+COUNTIF('CDG DC'!J20,"NC Majeure")+COUNTIF('CDG ITOC'!J20,"NC Majeure")+COUNTIF(BPOST!J20,"NC Majeure")+COUNTIF('Graphtalk AIA'!J20,"NC Majeure")+COUNTIF('ONCF APPS'!J20,"NC Majeure")+COUNTIF('ONCF MW'!J20,"NC Majeure")+COUNTIF(ANEF!J20,"NC Majeure")+COUNTIF(Carrefour!J20,"NC Majeure")+COUNTIF('Vinci Construction'!J20,"NC Majeure")+COUNTIF(AXA!J20,"NC Majeure")+COUNTIF(OCP!J20,"NC Majeure") -> 0 | E11: =COUNTIF('CDG Sécurité'!K20,"NC Mineure")+COUNTIF(RAM!J20,"NC Mineure")+COUNTIF('Min. Intérieur'!J20,"NC Mineure")+COUNTIF('CDG Capital'!J23,"NC Mineure")+COUNTIF(AtlanticRe!J20,"NC Mineure")+COUNTIF('Client A'!J20,"NC Mineure")+COUNTIF(Servier!J20,"NC Mineure")+COUNTIF(MEN!J20,"NC Mineure")+COUNTIF(ADM!J20,"NC Mineure")+COUNTIF('CDG DC'!J20,"NC Mineure")+COUNTIF('CDG ITOC'!J20,"NC Mineure")+COUNTIF(BPOST!J20,"NC Mineure")+COUNTIF('Graphtalk AIA'!J20,"NC Mineure")+COUNTIF('ONCF APPS'!J20,"NC Mineure")+COUNTIF('ONCF MW'!J20,"NC Mineure")+COUNTIF(ANEF!J20,"NC Mineure")+COUNTIF(Carrefour!J20,"NC Mineure")+COUNTIF('Vinci Construction'!J20,"NC Mineure")+COUNTIF(AXA!J20,"NC Mineure")+COUNTIF(OCP!J20,"NC Mineure") -> 0 | F11: =COUNTIF('CDG Sécurité'!K20,"Observation")+COUNTIF(RAM!J20,"Observation")+COUNTIF('Min. Intérieur'!J20,"Observation")+COUNTIF('CDG Capital'!J23,"Observation")+COUNTIF(AtlanticRe!J20,"Observation")+COUNTIF('Client A'!J20,"Observation")+COUNTIF(Servier!J20,"Observation")+COUNTIF(MEN!J20,"Observation")+COUNTIF(ADM!J20,"Observation")+COUNTIF('CDG DC'!J20,"Observation")+COUNTIF('CDG ITOC'!J20,"Observation")+COUNTIF(BPOST!J20,"Observation")+COUNTIF('Graphtalk AIA'!J20,"Observation")+COUNTIF('ONCF APPS'!J20,"Observation")+COUNTIF('ONCF MW'!J20,"Observation")+COUNTIF(ANEF!J20,"Observation")+COUNTIF(Carrefour!J20,"Observation")+COUNTIF('Vinci Construction'!J20,"Observation")+COUNTIF(AXA!J20,"Observation")+COUNTIF(OCP!J20,"Observation") -> 0 | G11: =COUNTIF('CDG Sécurité'!K20,"OFI")+COUNTIF(RAM!J20,"OFI")+COUNTIF('Min. Intérieur'!J20,"OFI")+COUNTIF('CDG Capital'!J23,"OFI")+COUNTIF(AtlanticRe!J20,"OFI")+COUNTIF('Client A'!J20,"OFI")+COUNTIF(Servier!J20,"OFI")+COUNTIF(MEN!J20,"OFI")+COUNTIF(ADM!J20,"OFI")+COUNTIF('CDG DC'!J20,"OFI")+COUNTIF('CDG ITOC'!J20,"OFI")+COUNTIF(BPOST!J20,"OFI")+COUNTIF('Graphtalk AIA'!J20,"OFI")+COUNTIF('ONCF APPS'!J20,"OFI")+COUNTIF('ONCF MW'!J20,"OFI")+COUNTIF(ANEF!J20,"OFI")+COUNTIF(Carrefour!J20,"OFI")+COUNTIF('Vinci Construction'!J20,"OFI")+COUNTIF(AXA!J20,"OFI")+COUNTIF(OCP!J20,"OFI") -> 0 | H11: =D11+E11+F11+G11 -> 0 | I11: =IFERROR(H11/H43,0) -> 0 | J11: =IF(D11>0,"🔴 Critique",IF(H11>5,"🟠 Fort",IF(H11>2,"🟡 Modéré",IF(H11>0,"🔵 Faible","✅ Aucun")))) -> ✅ Aucun
A12: 7 | B12: 5.3 | C12: Qui fait quoi ? | D12: =COUNTIF('CDG Sécurité'!K21,"NC Majeure")+COUNTIF(RAM!J21,"NC Majeure")+COUNTIF('Min. Intérieur'!J21,"NC Majeure")+COUNTIF('CDG Capital'!J24,"NC Majeure")+COUNTIF(AtlanticRe!J21,"NC Majeure")+COUNTIF('Client A'!J21,"NC Majeure")+COUNTIF(Servier!J21,"NC Majeure")+COUNTIF(MEN!J21,"NC Majeure")+COUNTIF(ADM!J21,"NC Majeure")+COUNTIF('CDG DC'!J21,"NC Majeure")+COUNTIF('CDG ITOC'!J21,"NC Majeure")+COUNTIF(BPOST!J21,"NC Majeure")+COUNTIF('Graphtalk AIA'!J21,"NC Majeure")+COUNTIF('ONCF APPS'!J21,"NC Majeure")+COUNTIF('ONCF MW'!J21,"NC Majeure")+COUNTIF(ANEF!J21,"NC Majeure")+COUNTIF(Carrefour!J21,"NC Majeure")+COUNTIF('Vinci Construction'!J21,"NC Majeure")+COUNTIF(AXA!J21,"NC Majeure")+COUNTIF(OCP!J21,"NC Majeure") -> 0 | E12: =COUNTIF('CDG Sécurité'!K21,"NC Mineure")+COUNTIF(RAM!J21,"NC Mineure")+COUNTIF('Min. Intérieur'!J21,"NC Mineure")+COUNTIF('CDG Capital'!J24,"NC Mineure")+COUNTIF(AtlanticRe!J21,"NC Mineure")+COUNTIF('Client A'!J21,"NC Mineure")+COUNTIF(Servier!J21,"NC Mineure")+COUNTIF(MEN!J21,"NC Mineure")+COUNTIF(ADM!J21,"NC Mineure")+COUNTIF('CDG DC'!J21,"NC Mineure")+COUNTIF('CDG ITOC'!J21,"NC Mineure")+COUNTIF(BPOST!J21,"NC Mineure")+COUNTIF('Graphtalk AIA'!J21,"NC Mineure")+COUNTIF('ONCF APPS'!J21,"NC Mineure")+COUNTIF('ONCF MW'!J21,"NC Mineure")+COUNTIF(ANEF!J21,"NC Mineure")+COUNTIF(Carrefour!J21,"NC Mineure")+COUNTIF('Vinci Construction'!J21,"NC Mineure")+COUNTIF(AXA!J21,"NC Mineure")+COUNTIF(OCP!J21,"NC Mineure") -> 0 | F12: =COUNTIF('CDG Sécurité'!K21,"Observation")+COUNTIF(RAM!J21,"Observation")+COUNTIF('Min. Intérieur'!J21,"Observation")+COUNTIF('CDG Capital'!J24,"Observation")+COUNTIF(AtlanticRe!J21,"Observation")+COUNTIF('Client A'!J21,"Observation")+COUNTIF(Servier!J21,"Observation")+COUNTIF(MEN!J21,"Observation")+COUNTIF(ADM!J21,"Observation")+COUNTIF('CDG DC'!J21,"Observation")+COUNTIF('CDG ITOC'!J21,"Observation")+COUNTIF(BPOST!J21,"Observation")+COUNTIF('Graphtalk AIA'!J21,"Observation")+COUNTIF('ONCF APPS'!J21,"Observation")+COUNTIF('ONCF MW'!J21,"Observation")+COUNTIF(ANEF!J21,"Observation")+COUNTIF(Carrefour!J21,"Observation")+COUNTIF('Vinci Construction'!J21,"Observation")+COUNTIF(AXA!J21,"Observation")+COUNTIF(OCP!J21,"Observation") -> 1 | G12: =COUNTIF('CDG Sécurité'!K21,"OFI")+COUNTIF(RAM!J21,"OFI")+COUNTIF('Min. Intérieur'!J21,"OFI")+COUNTIF('CDG Capital'!J24,"OFI")+COUNTIF(AtlanticRe!J21,"OFI")+COUNTIF('Client A'!J21,"OFI")+COUNTIF(Servier!J21,"OFI")+COUNTIF(MEN!J21,"OFI")+COUNTIF(ADM!J21,"OFI")+COUNTIF('CDG DC'!J21,"OFI")+COUNTIF('CDG ITOC'!J21,"OFI")+COUNTIF(BPOST!J21,"OFI")+COUNTIF('Graphtalk AIA'!J21,"OFI")+COUNTIF('ONCF APPS'!J21,"OFI")+COUNTIF('ONCF MW'!J21,"OFI")+COUNTIF(ANEF!J21,"OFI")+COUNTIF(Carrefour!J21,"OFI")+COUNTIF('Vinci Construction'!J21,"OFI")+COUNTIF(AXA!J21,"OFI")+COUNTIF(OCP!J21,"OFI") -> 0 | H12: =D12+E12+F12+G12 -> 1 | I12: =IFERROR(H12/H43,0) -> 0.019607843 | J12: =IF(D12>0,"🔴 Critique",IF(H12>5,"🟠 Fort",IF(H12>2,"🟡 Modéré",IF(H12>0,"🔵 Faible","✅ Aucun")))) -> 🔵 Faible
A13: 8 | B13: 6.1 | C13: Gestion des risques et opportunités | D13: =COUNTIF('CDG Sécurité'!K22,"NC Majeure")+COUNTIF(RAM!J22,"NC Majeure")+COUNTIF('Min. Intérieur'!J22,"NC Majeure")+COUNTIF('CDG Capital'!J25,"NC Majeure")+COUNTIF(AtlanticRe!J22,"NC Majeure")+COUNTIF('Client A'!J22,"NC Majeure")+COUNTIF(Servier!J22,"NC Majeure")+COUNTIF(MEN!J22,"NC Majeure")+COUNTIF(ADM!J22,"NC Majeure")+COUNTIF('CDG DC'!J22,"NC Majeure")+COUNTIF('CDG ITOC'!J22,"NC Majeure")+COUNTIF(BPOST!J22,"NC Majeure")+COUNTIF('Graphtalk AIA'!J22,"NC Majeure")+COUNTIF('ONCF APPS'!J22,"NC Majeure")+COUNTIF('ONCF MW'!J22,"NC Majeure")+COUNTIF(ANEF!J22,"NC Majeure")+COUNTIF(Carrefour!J22,"NC Majeure")+COUNTIF('Vinci Construction'!J22,"NC Majeure")+COUNTIF(AXA!J22,"NC Majeure")+COUNTIF(OCP!J22,"NC Majeure") -> 0 | E13: =COUNTIF('CDG Sécurité'!K22,"NC Mineure")+COUNTIF(RAM!J22,"NC Mineure")+COUNTIF('Min. Intérieur'!J22,"NC Mineure")+COUNTIF('CDG Capital'!J25,"NC Mineure")+COUNTIF(AtlanticRe!J22,"NC Mineure")+COUNTIF('Client A'!J22,"NC Mineure")+COUNTIF(Servier!J22,"NC Mineure")+COUNTIF(MEN!J22,"NC Mineure")+COUNTIF(ADM!J22,"NC Mineure")+COUNTIF('CDG DC'!J22,"NC Mineure")+COUNTIF('CDG ITOC'!J22,"NC Mineure")+COUNTIF(BPOST!J22,"NC Mineure")+COUNTIF('Graphtalk AIA'!J22,"NC Mineure")+COUNTIF('ONCF APPS'!J22,"NC Mineure")+COUNTIF('ONCF MW'!J22,"NC Mineure")+COUNTIF(ANEF!J22,"NC Mineure")+COUNTIF(Carrefour!J22,"NC Mineure")+COUNTIF('Vinci Construction'!J22,"NC Mineure")+COUNTIF(AXA!J22,"NC Mineure")+COUNTIF(OCP!J22,"NC Mineure") -> 8 | F13: =COUNTIF('CDG Sécurité'!K22,"Observation")+COUNTIF(RAM!J22,"Observation")+COUNTIF('Min. Intérieur'!J22,"Observation")+COUNTIF('CDG Capital'!J25,"Observation")+COUNTIF(AtlanticRe!J22,"Observation")+COUNTIF('Client A'!J22,"Observation")+COUNTIF(Servier!J22,"Observation")+COUNTIF(MEN!J22,"Observation")+COUNTIF(ADM!J22,"Observation")+COUNTIF('CDG DC'!J22,"Observation")+COUNTIF('CDG ITOC'!J22,"Observation")+COUNTIF(BPOST!J22,"Observation")+COUNTIF('Graphtalk AIA'!J22,"Observation")+COUNTIF('ONCF APPS'!J22,"Observation")+COUNTIF('ONCF MW'!J22,"Observation")+COUNTIF(ANEF!J22,"Observation")+COUNTIF(Carrefour!J22,"Observation")+COUNTIF('Vinci Construction'!J22,"Observation")+COUNTIF(AXA!J22,"Observation")+COUNTIF(OCP!J22,"Observation") -> 0 | G13: =COUNTIF('CDG Sécurité'!K22,"OFI")+COUNTIF(RAM!J22,"OFI")+COUNTIF('Min. Intérieur'!J22,"OFI")+COUNTIF('CDG Capital'!J25,"OFI")+COUNTIF(AtlanticRe!J22,"OFI")+COUNTIF('Client A'!J22,"OFI")+COUNTIF(Servier!J22,"OFI")+COUNTIF(MEN!J22,"OFI")+COUNTIF(ADM!J22,"OFI")+COUNTIF('CDG DC'!J22,"OFI")+COUNTIF('CDG ITOC'!J22,"OFI")+COUNTIF(BPOST!J22,"OFI")+COUNTIF('Graphtalk AIA'!J22,"OFI")+COUNTIF('ONCF APPS'!J22,"OFI")+COUNTIF('ONCF MW'!J22,"OFI")+COUNTIF(ANEF!J22,"OFI")+COUNTIF(Carrefour!J22,"OFI")+COUNTIF('Vinci Construction'!J22,"OFI")+COUNTIF(AXA!J22,"OFI")+COUNTIF(OCP!J22,"OFI") -> 0 | H13: =D13+E13+F13+G13 -> 8 | I13: =IFERROR(H13/H43,0) -> 0.15686275 | J13: =IF(D13>0,"🔴 Critique",IF(H13>5,"🟠 Fort",IF(H13>2,"🟡 Modéré",IF(H13>0,"🔵 Faible","✅ Aucun")))) -> 🟠 Fort
A14: 9 | B14: 6.2 | C14: Planification des objectifs | D14: =COUNTIF('CDG Sécurité'!K23,"NC Majeure")+COUNTIF(RAM!J23,"NC Majeure")+COUNTIF('Min. Intérieur'!J23,"NC Majeure")+COUNTIF('CDG Capital'!J29,"NC Majeure")+COUNTIF(AtlanticRe!J23,"NC Majeure")+COUNTIF('Client A'!J23,"NC Majeure")+COUNTIF(Servier!J23,"NC Majeure")+COUNTIF(MEN!J23,"NC Majeure")+COUNTIF(ADM!J23,"NC Majeure")+COUNTIF('CDG DC'!J23,"NC Majeure")+COUNTIF('CDG ITOC'!J23,"NC Majeure")+COUNTIF(BPOST!J23,"NC Majeure")+COUNTIF('Graphtalk AIA'!J23,"NC Majeure")+COUNTIF('ONCF APPS'!J23,"NC Majeure")+COUNTIF('ONCF MW'!J23,"NC Majeure")+COUNTIF(ANEF!J23,"NC Majeure")+COUNTIF(Carrefour!J23,"NC Majeure")+COUNTIF('Vinci Construction'!J23,"NC Majeure")+COUNTIF(AXA!J23,"NC Majeure")+COUNTIF(OCP!J23,"NC Majeure") -> 0 | E14: =COUNTIF('CDG Sécurité'!K23,"NC Mineure")+COUNTIF(RAM!J23,"NC Mineure")+COUNTIF('Min. Intérieur'!J23,"NC Mineure")+COUNTIF('CDG Capital'!J29,"NC Mineure")+COUNTIF(AtlanticRe!J23,"NC Mineure")+COUNTIF('Client A'!J23,"NC Mineure")+COUNTIF(Servier!J23,"NC Mineure")+COUNTIF(MEN!J23,"NC Mineure")+COUNTIF(ADM!J23,"NC Mineure")+COUNTIF('CDG DC'!J23,"NC Mineure")+COUNTIF('CDG ITOC'!J23,"NC Mineure")+COUNTIF(BPOST!J23,"NC Mineure")+COUNTIF('Graphtalk AIA'!J23,"NC Mineure")+COUNTIF('ONCF APPS'!J23,"NC Mineure")+COUNTIF('ONCF MW'!J23,"NC Mineure")+COUNTIF(ANEF!J23,"NC Mineure")+COUNTIF(Carrefour!J23,"NC Mineure")+COUNTIF('Vinci Construction'!J23,"NC Mineure")+COUNTIF(AXA!J23,"NC Mineure")+COUNTIF(OCP!J23,"NC Mineure") -> 2 | F14: =COUNTIF('CDG Sécurité'!K23,"Observation")+COUNTIF(RAM!J23,"Observation")+COUNTIF('Min. Intérieur'!J23,"Observation")+COUNTIF('CDG Capital'!J29,"Observation")+COUNTIF(AtlanticRe!J23,"Observation")+COUNTIF('Client A'!J23,"Observation")+COUNTIF(Servier!J23,"Observation")+COUNTIF(MEN!J23,"Observation")+COUNTIF(ADM!J23,"Observation")+COUNTIF('CDG DC'!J23,"Observation")+COUNTIF('CDG ITOC'!J23,"Observation")+COUNTIF(BPOST!J23,"Observation")+COUNTIF('Graphtalk AIA'!J23,"Observation")+COUNTIF('ONCF APPS'!J23,"Observation")+COUNTIF('ONCF MW'!J23,"Observation")+COUNTIF(ANEF!J23,"Observation")+COUNTIF(Carrefour!J23,"Observation")+COUNTIF('Vinci Construction'!J23,"Observation")+COUNTIF(AXA!J23,"Observation")+COUNTIF(OCP!J23,"Observation") -> 0 | G14: =COUNTIF('CDG Sécurité'!K23,"OFI")+COUNTIF(RAM!J23,"OFI")+COUNTIF('Min. Intérieur'!J23,"OFI")+COUNTIF('CDG Capital'!J29,"OFI")+COUNTIF(AtlanticRe!J23,"OFI")+COUNTIF('Client A'!J23,"OFI")+COUNTIF(Servier!J23,"OFI")+COUNTIF(MEN!J23,"OFI")+COUNTIF(ADM!J23,"OFI")+COUNTIF('CDG DC'!J23,"OFI")+COUNTIF('CDG ITOC'!J23,"OFI")+COUNTIF(BPOST!J23,"OFI")+COUNTIF('Graphtalk AIA'!J23,"OFI")+COUNTIF('ONCF APPS'!J23,"OFI")+COUNTIF('ONCF MW'!J23,"OFI")+COUNTIF(ANEF!J23,"OFI")+COUNTIF(Carrefour!J23,"OFI")+COUNTIF('Vinci Construction'!J23,"OFI")+COUNTIF(AXA!J23,"OFI")+COUNTIF(OCP!J23,"OFI") -> 0 | H14: =D14+E14+F14+G14 -> 2 | I14: =IFERROR(H14/H43,0) -> 0.039215686 | J14: =IF(D14>0,"🔴 Critique",IF(H14>5,"🟠 Fort",IF(H14>2,"🟡 Modéré",IF(H14>0,"🔵 Faible","✅ Aucun")))) -> 🔵 Faible
A15: 10 | B15: 6.3 | C15: Gestion des changements | D15: =COUNTIF('CDG Sécurité'!K24,"NC Majeure")+COUNTIF(RAM!J24,"NC Majeure")+COUNTIF('Min. Intérieur'!J24,"NC Majeure")+COUNTIF('CDG Capital'!J30,"NC Majeure")+COUNTIF(AtlanticRe!J24,"NC Majeure")+COUNTIF('Client A'!J24,"NC Majeure")+COUNTIF(Servier!J24,"NC Majeure")+COUNTIF(MEN!J24,"NC Majeure")+COUNTIF(ADM!J24,"NC Majeure")+COUNTIF('CDG DC'!J24,"NC Majeure")+COUNTIF('CDG ITOC'!J24,"NC Majeure")+COUNTIF(BPOST!J24,"NC Majeure")+COUNTIF('Graphtalk AIA'!J24,"NC Majeure")+COUNTIF('ONCF APPS'!J24,"NC Majeure")+COUNTIF('ONCF MW'!J24,"NC Majeure")+COUNTIF(ANEF!J24,"NC Majeure")+COUNTIF(Carrefour!J24,"NC Majeure")+COUNTIF('Vinci Construction'!J24,"NC Majeure")+COUNTIF(AXA!J24,"NC Majeure")+COUNTIF(OCP!J24,"NC Majeure") -> 0 | E15: =COUNTIF('CDG Sécurité'!K24,"NC Mineure")+COUNTIF(RAM!J24,"NC Mineure")+COUNTIF('Min. Intérieur'!J24,"NC Mineure")+COUNTIF('CDG Capital'!J30,"NC Mineure")+COUNTIF(AtlanticRe!J24,"NC Mineure")+COUNTIF('Client A'!J24,"NC Mineure")+COUNTIF(Servier!J24,"NC Mineure")+COUNTIF(MEN!J24,"NC Mineure")+COUNTIF(ADM!J24,"NC Mineure")+COUNTIF('CDG DC'!J24,"NC Mineure")+COUNTIF('CDG ITOC'!J24,"NC Mineure")+COUNTIF(BPOST!J24,"NC Mineure")+COUNTIF('Graphtalk AIA'!J24,"NC Mineure")+COUNTIF('ONCF APPS'!J24,"NC Mineure")+COUNTIF('ONCF MW'!J24,"NC Mineure")+COUNTIF(ANEF!J24,"NC Mineure")+COUNTIF(Carrefour!J24,"NC Mineure")+COUNTIF('Vinci Construction'!J24,"NC Mineure")+COUNTIF(AXA!J24,"NC Mineure")+COUNTIF(OCP!J24,"NC Mineure") -> 3 | F15: =COUNTIF('CDG Sécurité'!K24,"Observation")+COUNTIF(RAM!J24,"Observation")+COUNTIF('Min. Intérieur'!J24,"Observation")+COUNTIF('CDG Capital'!J30,"Observation")+COUNTIF(AtlanticRe!J24,"Observation")+COUNTIF('Client A'!J24,"Observation")+COUNTIF(Servier!J24,"Observation")+COUNTIF(MEN!J24,"Observation")+COUNTIF(ADM!J24,"Observation")+COUNTIF('CDG DC'!J24,"Observation")+COUNTIF('CDG ITOC'!J24,"Observation")+COUNTIF(BPOST!J24,"Observation")+COUNTIF('Graphtalk AIA'!J24,"Observation")+COUNTIF('ONCF APPS'!J24,"Observation")+COUNTIF('ONCF MW'!J24,"Observation")+COUNTIF(ANEF!J24,"Observation")+COUNTIF(Carrefour!J24,"Observation")+COUNTIF('Vinci Construction'!J24,"Observation")+COUNTIF(AXA!J24,"Observation")+COUNTIF(OCP!J24,"Observation") -> 0 | G15: =COUNTIF('CDG Sécurité'!K24,"OFI")+COUNTIF(RAM!J24,"OFI")+COUNTIF('Min. Intérieur'!J24,"OFI")+COUNTIF('CDG Capital'!J30,"OFI")+COUNTIF(AtlanticRe!J24,"OFI")+COUNTIF('Client A'!J24,"OFI")+COUNTIF(Servier!J24,"OFI")+COUNTIF(MEN!J24,"OFI")+COUNTIF(ADM!J24,"OFI")+COUNTIF('CDG DC'!J24,"OFI")+COUNTIF('CDG ITOC'!J24,"OFI")+COUNTIF(BPOST!J24,"OFI")+COUNTIF('Graphtalk AIA'!J24,"OFI")+COUNTIF('ONCF APPS'!J24,"OFI")+COUNTIF('ONCF MW'!J24,"OFI")+COUNTIF(ANEF!J24,"OFI")+COUNTIF(Carrefour!J24,"OFI")+COUNTIF('Vinci Construction'!J24,"OFI")+COUNTIF(AXA!J24,"OFI")+COUNTIF(OCP!J24,"OFI") -> 0 | H15: =D15+E15+F15+G15 -> 3 | I15: =IFERROR(H15/H43,0) -> 0.058823529 | J15: =IF(D15>0,"🔴 Critique",IF(H15>5,"🟠 Fort",IF(H15>2,"🟡 Modéré",IF(H15>0,"🔵 Faible","✅ Aucun")))) -> 🟡 Modéré
A16: 11 | B16: 7.1.1 | C16: Disponibilité des ressources humaines | D16: =COUNTIF('CDG Sécurité'!K25,"NC Majeure")+COUNTIF(RAM!J25,"NC Majeure")+COUNTIF('Min. Intérieur'!J25,"NC Majeure")+COUNTIF('CDG Capital'!J31,"NC Majeure")+COUNTIF(AtlanticRe!J25,"NC Majeure")+COUNTIF('Client A'!J25,"NC Majeure")+COUNTIF(Servier!J25,"NC Majeure")+COUNTIF(MEN!J25,"NC Majeure")+COUNTIF(ADM!J25,"NC Majeure")+COUNTIF('CDG DC'!J25,"NC Majeure")+COUNTIF('CDG ITOC'!J25,"NC Majeure")+COUNTIF(BPOST!J25,"NC Majeure")+COUNTIF('Graphtalk AIA'!J25,"NC Majeure")+COUNTIF('ONCF APPS'!J25,"NC Majeure")+COUNTIF('ONCF MW'!J25,"NC Majeure")+COUNTIF(ANEF!J25,"NC Majeure")+COUNTIF(Carrefour!J25,"NC Majeure")+COUNTIF('Vinci Construction'!J25,"NC Majeure")+COUNTIF(AXA!J25,"NC Majeure")+COUNTIF(OCP!J25,"NC Majeure") -> 0 | E16: =COUNTIF('CDG Sécurité'!K25,"NC Mineure")+COUNTIF(RAM!J25,"NC Mineure")+COUNTIF('Min. Intérieur'!J25,"NC Mineure")+COUNTIF('CDG Capital'!J31,"NC Mineure")+COUNTIF(AtlanticRe!J25,"NC Mineure")+COUNTIF('Client A'!J25,"NC Mineure")+COUNTIF(Servier!J25,"NC Mineure")+COUNTIF(MEN!J25,"NC Mineure")+COUNTIF(ADM!J25,"NC Mineure")+COUNTIF('CDG DC'!J25,"NC Mineure")+COUNTIF('CDG ITOC'!J25,"NC Mineure")+COUNTIF(BPOST!J25,"NC Mineure")+COUNTIF('Graphtalk AIA'!J25,"NC Mineure")+COUNTIF('ONCF APPS'!J25,"NC Mineure")+COUNTIF('ONCF MW'!J25,"NC Mineure")+COUNTIF(ANEF!J25,"NC Mineure")+COUNTIF(Carrefour!J25,"NC Mineure")+COUNTIF('Vinci Construction'!J25,"NC Mineure")+COUNTIF(AXA!J25,"NC Mineure")+COUNTIF(OCP!J25,"NC Mineure") -> 0 | F16: =COUNTIF('CDG Sécurité'!K25,"Observation")+COUNTIF(RAM!J25,"Observation")+COUNTIF('Min. Intérieur'!J25,"Observation")+COUNTIF('CDG Capital'!J31,"Observation")+COUNTIF(AtlanticRe!J25,"Observation")+COUNTIF('Client A'!J25,"Observation")+COUNTIF(Servier!J25,"Observation")+COUNTIF(MEN!J25,"Observation")+COUNTIF(ADM!J25,"Observation")+COUNTIF('CDG DC'!J25,"Observation")+COUNTIF('CDG ITOC'!J25,"Observation")+COUNTIF(BPOST!J25,"Observation")+COUNTIF('Graphtalk AIA'!J25,"Observation")+COUNTIF('ONCF APPS'!J25,"Observation")+COUNTIF('ONCF MW'!J25,"Observation")+COUNTIF(ANEF!J25,"Observation")+COUNTIF(Carrefour!J25,"Observation")+COUNTIF('Vinci Construction'!J25,"Observation")+COUNTIF(AXA!J25,"Observation")+COUNTIF(OCP!J25,"Observation") -> 1 | G16: =COUNTIF('CDG Sécurité'!K25,"OFI")+COUNTIF(RAM!J25,"OFI")+COUNTIF('Min. Intérieur'!J25,"OFI")+COUNTIF('CDG Capital'!J31,"OFI")+COUNTIF(AtlanticRe!J25,"OFI")+COUNTIF('Client A'!J25,"OFI")+COUNTIF(Servier!J25,"OFI")+COUNTIF(MEN!J25,"OFI")+COUNTIF(ADM!J25,"OFI")+COUNTIF('CDG DC'!J25,"OFI")+COUNTIF('CDG ITOC'!J25,"OFI")+COUNTIF(BPOST!J25,"OFI")+COUNTIF('Graphtalk AIA'!J25,"OFI")+COUNTIF('ONCF APPS'!J25,"OFI")+COUNTIF('ONCF MW'!J25,"OFI")+COUNTIF(ANEF!J25,"OFI")+COUNTIF(Carrefour!J25,"OFI")+COUNTIF('Vinci Construction'!J25,"OFI")+COUNTIF(AXA!J25,"OFI")+COUNTIF(OCP!J25,"OFI") -> 0 | H16: =D16+E16+F16+G16 -> 1 | I16: =IFERROR(H16/H43,0) -> 0.019607843 | J16: =IF(D16>0,"🔴 Critique",IF(H16>5,"🟠 Fort",IF(H16>2,"🟡 Modéré",IF(H16>0,"🔵 Faible","✅ Aucun")))) -> 🔵 Faible
